Workbook

Sheet 표지
B6: 내부솔루션(VIOLA) 4.0
E25: 기능 테스트 케이스
F26: 작성일 : 26.09.01

Sheet 문서버전
B2: 변경이력관리
B3: 변경일 | C3: 버전명 | D3: 변경내역 | E3: 변경 인원 | F3: 비고

Sheet Summary
B2: ▶︎ 요약
B3: 프로젝트명 | C3: 내부솔루션 VIOLA V4.0 검증
B4: 검증 환경
B5: 검증 버전 | C5: V4.0
B6: 검증 솔루션 | C6: VIOLA
B7: 검증 일정
B8: 배포일
B9: Figma URL | C9: K8s / CICD
B11: ▶︎ 단위테스트 현황
B12: 구분 | D12: 테스트 결과 | H12: Testcase | I12: 수행률 | J12: 성공률 | K12: 비고
D13: PASS | E13: FAIL | F13: N/A | G13: N/T
B14: VIOLA_K8s | D14: =COUNTIFS('VIOLA(4.0)_신규변경'!$R$2:$R$12063,D$13,'VIOLA(4.0)_신규변경'!$B$2:$B$12063,$B$14) -> 281 | E14: =COUNTIFS('VIOLA(4.0)_신규변경'!$R$2:$R$12063,E$13,'VIOLA(4.0)_신규변경'!$B$2:$B$12063,$B$14) -> 6 | F14: =COUNTIFS('VIOLA(4.0)_신규변경'!$R$2:$R$12063,F$13,'VIOLA(4.0)_신규변경'!$B$2:$B$12063,$B$14) -> 6 | G14: =COUNTIFS('VIOLA(4.0)_신규변경'!$R$2:$R$12063,G$13,'VIOLA(4.0)_신규변경'!$B$2:$B$12063,$B$14) -> 0 | H14: =COUNTIF('VIOLA(4.0)_신규변경'!$B$2:$B$12075,$B$14)-G14 -> 2524 | I14: =IFERROR((D14+E14)/H14,"-") -> 0.1137084 | J14: =IFERROR(D14/(D14+E14),"-") -> 0.97909408
B15: VIOLA_CICD | D15: =COUNTIFS('VIOLA(4.0)_신규변경'!$R$2:$R$12063,D$13,'VIOLA(4.0)_신규변경'!$B$2:$B$12063,$B$15) -> 0 | E15: =COUNTIFS('VIOLA(4.0)_신규변경'!$R$2:$R$12063,E$13,'VIOLA(4.0)_신규변경'!$B$2:$B$12063,$B$15) -> 0 | F15: =COUNTIFS('VIOLA(4.0)_신규변경'!$R$2:$R$12063,F$13,'VIOLA(4.0)_신규변경'!$B$2:$B$12063,$B$15) -> 0 | G15: =COUNTIFS('VIOLA(4.0)_신규변경'!$R$2:$R$12063,G$13,'VIOLA(4.0)_신규변경'!$B$2:$B$12063,$B$15) -> 0 | H15: =COUNTIF('VIOLA(4.0)_신규변경'!$B$2:$B$12075,$B$15)-G15 -> 0 | I15: =IFERROR((D15+E15)/H15,"-") -> - | J15: =IFERROR(D15/(D15+E15),"-") -> -
B16: 총합 | D16: =SUM(D14:D15) -> 281 | E16: =SUM(E14:E15) -> 6 | F16: =SUM(F14:F15) -> 6 | G16: =SUM(G14:G15) -> 0 | H16: =SUM(H14:H15) -> 2524 | I16: =IFERROR((D16+E16)/H16,"-") -> 0.1137084 | J16: =IFERROR(D16/(D16+E16),"-") -> 0.97909408
B17: * 6/8 18:00 기준
B19: ▶︎ 심각도별 테스트 현황
B20: 구분 | C20: 테스트 결과 | H20: Testcase | I20: 수행률 | J20: 성공률 | K20: 비고
C21: 심각도 | D21: PASS | E21: FAIL | F21: N/A | G21: N/T
B22: VIOLA | C22: P1 | D22: =COUNTIFS('VIOLA(4.0)_신규변경'!$G$2:$G$12063, $C22,'VIOLA(4.0)_신규변경'!$R$2:$R$12063,D$13) -> 17 | E22: =COUNTIFS('VIOLA(4.0)_신규변경'!$G$2:$G$12063, $C22,'VIOLA(4.0)_신규변경'!$R$2:$R$12063,E$13) -> 0 | F22: =COUNTIFS('VIOLA(4.0)_신규변경'!$G$2:$G$12063, $C22,'VIOLA(4.0)_신규변경'!$R$2:$R$12063,F$13) -> 0 | G22: =COUNTIFS('VIOLA(4.0)_신규변경'!$G$2:$G$12063, $C22,'VIOLA(4.0)_신규변경'!$R$2:$R$12063,G$13) -> 0 | H22: =COUNTIF('VIOLA(4.0)_신규변경'!$G$2:$G$12063, $C22)-G22 -> 75 | I22: =IFERROR((D22+E22)/H22,"-") -> 0.22666667 | J22: =IFERROR(D22/(D22+E22),"-") -> 1
C23: P2 | D23: =COUNTIFS('VIOLA(4.0)_신규변경'!$G$2:$G$12063, $C23,'VIOLA(4.0)_신규변경'!$R$2:$R$12063,D$13) -> 16 | E23: =COUNTIFS('VIOLA(4.0)_신규변경'!$G$2:$G$12063, $C23,'VIOLA(4.0)_신규변경'!$R$2:$R$12063,E$13) -> 0 | F23: =COUNTIFS('VIOLA(4.0)_신규변경'!$G$2:$G$12063, $C23,'VIOLA(4.0)_신규변경'!$R$2:$R$12063,F$13) -> 0 | G23: =COUNTIFS('VIOLA(4.0)_신규변경'!$G$2:$G$12063, $C23,'VIOLA(4.0)_신규변경'!$R$2:$R$12063,G$13) -> 0 | H23: =COUNTIF('VIOLA(4.0)_신규변경'!$G$2:$G$12063, $C23)-G23 -> 122 | I23: =IFERROR((D23+E23)/H23,"-") -> 0.13114754 | J23: =IFERROR(D23/(D23+E23),"-") -> 1
C24: P3 | D24: =COUNTIFS('VIOLA(4.0)_신규변경'!$G$2:$G$12063, $C24,'VIOLA(4.0)_신규변경'!$R$2:$R$12063,D$13) -> 239 | E24: =COUNTIFS('VIOLA(4.0)_신규변경'!$G$2:$G$12063, $C24,'VIOLA(4.0)_신규변경'!$R$2:$R$12063,E$13) -> 5 | F24: =COUNTIFS('VIOLA(4.0)_신규변경'!$G$2:$G$12063, $C24,'VIOLA(4.0)_신규변경'!$R$2:$R$12063,F$13) -> 6 | G24: =COUNTIFS('VIOLA(4.0)_신규변경'!$G$2:$G$12063, $C24,'VIOLA(4.0)_신규변경'!$R$2:$R$12063,G$13) -> 0 | H24: =COUNTIF('VIOLA(4.0)_신규변경'!$G$2:$G$12063, $C24)-G24 -> 2281 | I24: =IFERROR((D24+E24)/H24,"-") -> 0.10697063 | J24: =IFERROR(D24/(D24+E24),"-") -> 0.9795082
C25: P4 | D25: =COUNTIFS('VIOLA(4.0)_신규변경'!$G$2:$G$12063, $C25,'VIOLA(4.0)_신규변경'!$R$2:$R$12063,D$13) -> 9 | E25: =COUNTIFS('VIOLA(4.0)_신규변경'!$G$2:$G$12063, $C25,'VIOLA(4.0)_신규변경'!$R$2:$R$12063,E$13) -> 1 | F25: =COUNTIFS('VIOLA(4.0)_신규변경'!$G$2:$G$12063, $C25,'VIOLA(4.0)_신규변경'!$R$2:$R$12063,F$13) -> 0 | G25: =COUNTIFS('VIOLA(4.0)_신규변경'!$G$2:$G$12063, $C25,'VIOLA(4.0)_신규변경'!$R$2:$R$12063,G$13) -> 0 | H25: =COUNTIF('VIOLA(4.0)_신규변경'!$G$2:$G$12063, $C25)-G25 -> 46 | I25: =IFERROR((D25+E25)/H25,"-") -> 0.2173913 | J25: =IFERROR(D25/(D25+E25),"-") -> 0.9
C26: 총합 | D26: =SUM(D22:D25) -> 281 | E26: =SUM(E22:E25) -> 6 | F26: =SUM(F22:F25) -> 6 | G26: =SUM(G22:G25) -> 0 | H26: =SUM(H22:H25) -> 2524 | I26: =IFERROR((D26+E26)/H26,"-") -> 0.1137084 | J26: =IFERROR(D26/(D26+E26),"-") -> 0.97909408
B27: * 6/8 18:00 기준
B29: 1. 테스트 이슈 (테스트 환경 및 개발 이슈) 2. 주요 결함 3. 특이사항

Sheet VIOLA(4.0)_신규변경
A1: No | B1: 솔루션 | C1: 기능테스트 ID | D1: 요구사항 ID | E1: 기능 ID | F1: 화면 ID | G1: 우선순위 | H1: 구분 | I1: 1 Depth | J1: 2 Depth | K1: 3 Depth | L1: 4 Depth | M1: 5 Depth | N1: 사전조건 | O1: 테스트 데이터 | P1: 절차 | Q1: 예상 결과 | R1: 실제 결과 | S1: 수행자 | T1: 수행일자 | U1: Jira | V1: 비고
A2: =ROW()-1 -> 1 | B2: VIOLA_K8S | C2: TC_VIO_001 | F2: VIOE-00_00_00 | G2: P3 | H2: 표시 | I2: 공통 정의 | J2: 레이아웃 정의 | K2: 상세 | L2: - | M2: - | N2: VIOLA 로그인 후 레이아웃이 적용된 화면 진입 | P2: 1. 화면 상단 GNB 영역 확인 | Q2: GNB 영역 구성 확인 | R2: PASS | S2: 김미지 | T2: 46296
A3: =ROW()-1 -> 2 | B3: VIOLA_K8S | C3: TC_VIO_002 | F3: VIOE-00_00_00 | G3: P3 | H3: 표시 | I3: 공통 정의 | J3: 레이아웃 정의 | K3: 상세 | L3: - | M3: - | N3: 레이아웃 적용 화면 진입 직후 상태 | P3: 1. LNB 영역의 메뉴 목록 확인 | Q3: 메뉴 `대시보드`·`기본 설정`·`워크플로우`·`서비스 카탈로그`·`모니터링` 5종 표출 | R3: PASS | S3: 김미지 | T3: 46296
A4: =ROW()-1 -> 3 | B4: VIOLA_K8S | C4: TC_VIO_003 | F4: VIOE-00_00_00 | G4: P3 | H4: 표시 | I4: 공통 정의 | J4: 레이아웃 정의 | K4: 상세 | L4: - | M4: - | N4: 레이아웃 적용 화면 진입 직후 상태 | P4: 1. LNB 메뉴 목록을 Menu Structure 정의와 대조 | Q4: LNB 메뉴 구성 확인 ㄴ 기획 미정의 항목 — PASS/FAIL 판정 대신 실측 상태를 `실제 결과`에 기재 | R4: PASS | S4: 김미지 | T4: 46296
A5: =ROW()-1 -> 4 | B5: VIOLA_K8S | C5: TC_VIO_004 | F5: VIOE-00_00_00 | G5: P3 | H5: 표시 | I5: 공통 정의 | J5: 레이아웃 정의 | K5: 상세 | L5: - | M5: - | N5: 레이아웃 적용 화면 최초 진입 상태 | P5: 1. LNB 상위 메뉴의 펼침 상태 확인 | Q5: 전체 메뉴 닫힘 상태로 표출 | R5: PASS | S5: 김미지 | T5: 46296
A6: =ROW()-1 -> 5 | B6: VIOLA_K8S | C6: TC_VIO_005 | F6: VIOE-00_00_00 | G6: P3 | H6: 표시 | I6: 공통 정의 | J6: 레이아웃 정의 | K6: 상세 | L6: - | M6: - | N6: 레이아웃 적용 화면 최초 진입 상태 | P6: 1. 테넌트 네비게이터 선택 후 LNB 확인 | Q6: `대시보드` 메뉴 선택 상태로 표출 | R6: PASS | S6: 김미지 | T6: 46296
A7: =ROW()-1 -> 6 | B7: VIOLA_K8S | C7: TC_VIO_006 | F7: VIOE-00_00_00 | G7: P3 | H7: 표시 | I7: 공통 정의 | J7: 레이아웃 정의 | K7: 상세 | L7: - | M7: - | N7: 레이아웃 적용 화면 최초 진입 상태 | P7: 1. 하위 메뉴 보유 메뉴의 chevron 표기 확인 | Q7: `기본 설정`·`워크플로우`·`서비스 카탈로그`·`모니터링` 우측에 chevron `˅` 표출 | R7: PASS | S7: 김미지 | T7: 46296
A8: =ROW()-1 -> 7 | B8: VIOLA_K8S | C8: TC_VIO_007 | F8: VIOE-00_00_00 | G8: P4 | H8: 부수 | I8: 공통 정의 | J8: 레이아웃 정의 | K8: 상세 | L8: - | M8: - | N8: LNB 전체 메뉴 닫힘 상태 | P8: 1. 하위 메뉴가 없는 `대시보드` 메뉴 클릭 | Q8: chevron 미표기로 하위 메뉴 펼침 미발생 | R8: PASS | S8: 김미지 | T8: 46296
A9: =ROW()-1 -> 8 | B9: VIOLA_K8S | C9: TC_VIO_008 | F9: VIOE-00_00_00 | G9: P3 | H9: 인터랙션 | I9: 공통 정의 | J9: 레이아웃 정의 | K9: 상세 | L9: - | M9: - | N9: LNB 전체 메뉴 닫힘 상태 | P9: 1. 상위 메뉴 `기본 설정` 클릭 | Q9: `기본 설정` 하위 메뉴 펼침 | R9: PASS | S9: 김미지 | T9: 46296
A10: =ROW()-1 -> 9 | B10: VIOLA_K8S | C10: TC_VIO_009 | F10: VIOE-00_00_00 | G10: P3 | H10: 엣지 | I10: 공통 정의 | J10: 레이아웃 정의 | K10: 상세 | L10: - | M10: - | N10: 상위 메뉴 `기본 설정` 하위 메뉴가 펼쳐진 상태 | P10: 1. 상위 메뉴 `기본 설정` 재클릭 | Q10: 기본 설정' 하위 메뉴 닫힘 | R10: PASS | S10: 김미지 | T10: 46296
A11: =ROW()-1 -> 10 | B11: VIOLA_K8S | C11: TC_VIO_010 | F11: VIOE-00_00_00 | G11: P3 | H11: 엣지 | I11: 공통 정의 | J11: 레이아웃 정의 | K11: 상세 | L11: - | M11: - | N11: 상위 메뉴 `기본 설정` 하위 메뉴가 펼쳐진 상태 | P11: 1. 다른 상위 메뉴 `워크플로우` 클릭 | Q11: 두 상위 메뉴의 펼침 상태 확인 | R11: PASS | S11: 김미지 | T11: 46296
A12: =ROW()-1 -> 11 | B12: VIOLA_K8S | C12: TC_VIO_011 | F12: VIOE-00_00_00 | G12: P3 | H12: 엣지 | I12: 공통 정의 | J12: 레이아웃 정의 | K12: 상세 | L12: - | M12: - | N12: 복수 상위 메뉴의 하위 메뉴가 펼쳐진 상태 | P12: 1. 하위 메뉴가 없는 메뉴 진입 | Q12: 진입한 메뉴 외 전체 메뉴 닫힘 | R12: PASS | S12: 김미지 | T12: 46296
A13: =ROW()-1 -> 12 | B13: VIOLA_K8S | C13: TC_VIO_012 | F13: VIOE-00_00_00 | G13: P3 | H13: 엣지 | I13: 공통 정의 | J13: 레이아웃 정의 | K13: 상세 | L13: - | M13: - | N13: 상위 메뉴 하위의 하위 메뉴 없는 메뉴에 진입한 상태 | P13: 1. 진입한 메뉴의 상위 메뉴 펼침 상태 확인 | Q13: 진입한 메뉴의 상위 메뉴만 펼침 상태 유지 | R13: PASS | S13: 김미지 | T13: 46296
... A20: =ROW()-1 -> 19 | B20: VIOLA_K8S | C20: TC_VIO_030 | F20: VIOE-00_00_00 | G20: P3 | H20: 표시 | I20: 공통 정의 | J20: 레이아웃 정의 | K20: 상세 | L20: - | M20: - | N20: 레이아웃 적용 화면 진입 직후 상태 | P20: 1. `모니터링 현황` 버튼의 활성 상태 확인 | Q20: 버튼 항상 활성 상태로 표출 | R20: PASS | S20: 김미지 | T20: 46296
A21: =ROW()-1 -> 20 | B21: VIOLA_K8S | C21: TC_VIO_031 | F21: VIOE-00_00_00 | G21: P3 | H21: 엣지 | I21: 공통 정의 | J21: 레이아웃 정의 | K21: 상세 | L21: - | M21: - | N21: 모니터링 현황 정보 내 장애가 발생한 상태 | P21: 1. 상단 바 `모니터링 현황` 버튼의 알림 효과 확인 | Q21: 시각적 알림 효과 표출 ㄴ 효과 형태(색·애니메이션·배지) 기획 미정의 — 형태는 실측 상태를 `실제 결과`에 기재
A22: =ROW()-1 -> 21 | B22: VIOLA_K8S | C22: TC_VIO_033 | F22: VIOE-00_00_00 | G22: P1 | H22: 인터랙션 | I22: 공통 정의 | J22: 레이아웃 정의 | K22: 상세 | L22: - | M22: - | N22: 상단 바 `모니터링 현황` 버튼이 표출된 상태 | P22: 1. `모니터링 현황` 버튼 클릭 | Q22: 오버레이 팝업 표출 | R22: PASS | S22: 김미지 | T22: 46296
A23: =ROW()-1 -> 22 | B23: VIOLA_K8S | C23: TC_VIO_037 | F23: VIOE-00_00_00 | G23: P3 | H23: 표시 | I23: 공통 정의 | J23: 테넌트 네비게이터 팝오버 | K23: 상세 | L23: - | M23: - | N23: 테넌트 네비게이터 팝오버가 표출된 상태 | P23: 1. 팝오버 상단 라벨 확인 | Q23: 라벨 `클러스터 선택` 표출 | R23: PASS | S23: 김미지 | T23: 46296
A24: =ROW()-1 -> 23 | B24: VIOLA_K8S | C24: TC_VIO_038 | F24: VIOE-00_00_00 | G24: P3 | H24: 표시 | I24: 공통 정의 | J24: 테넌트 네비게이터 팝오버 | K24: 상세 | L24: - | M24: - | N24: 테넌트 네비게이터 팝오버가 표출된 상태 | P24: 1. 팝오버 검색 입력 필드 확인 | Q24: 돋보기 아이콘과 placeholder 텍스트 표출 | R24: PASS | S24: 김미지 | T24: 46296
A25: =ROW()-1 -> 24 | B25: VIOLA_K8S | C25: TC_VIO_039 | F25: VIOE-00_00_00 | G25: P3 | H25: 표시 | I25: 공통 정의 | J25: 테넌트 네비게이터 팝오버 | K25: 상세 | L25: - | M25: - | N25: 테넌트 네비게이터 팝오버가 표출된 상태 | P25: 1. 팝오버 상단 그룹 헤더 확인 | Q25: 그룹 헤더 `즐겨찾기` 표출 | R25: PASS | S25: 김미지 | T25: 46296
A26: =ROW()-1 -> 25 | B26: VIOLA_K8S | C26: TC_VIO_040 | F26: VIOE-00_00_00 | G26: P3 | H26: 표시 | I26: 공통 정의 | J26: 테넌트 네비게이터 팝오버 | K26: 상세 | L26: - | M26: - | N26: 테넌트 네비게이터 팝오버가 표출된 상태 | P26: 1. 팝오버 하단 그룹 헤더 확인 | Q26: 그룹 헤더 `전체` 표출 | R26: PASS | S26: 김미지 | T26: 46296
A27: =ROW()-1 -> 26 | B27: VIOLA_K8S | C27: TC_VIO_041 | F27: VIOE-00_00_00 | G27: P3 | H27: 표시 | I27: 공통 정의 | J27: 테넌트 네비게이터 팝오버 | K27: 상세 | L27: - | M27: - | N27: 테넌트 네비게이터 팝오버가 표출된 상태 | P27: 1. 그룹 사이 구분선 확인 | Q27: 그룹 사이 수평 구분선 1개 표출 | R27: PASS | S27: 김미지 | T27: 46296
A28: =ROW()-1 -> 27 | B28: VIOLA_K8S | C28: TC_VIO_042 | F28: VIOE-00_00_00 | G28: P3 | H28: 표시 | I28: 공통 정의 | J28: 테넌트 네비게이터 팝오버 | K28: 상세 | L28: - | M28: - | N28: 테넌트 네비게이터 팝오버가 표출된 상태 | P28: 1. `즐겨찾기` 그룹 항목의 북마크 아이콘 확인 | Q28: 녹색 채움 북마크 아이콘 표출 | R28: PASS | S28: 김미지 | T28: 46296
A29: =ROW()-1 -> 28 | B29: VIOLA_K8S | C29: TC_VIO_043 | F29: VIOE-00_00_00 | G29: P3 | H29: 표시 | I29: 공통 정의 | J29: 테넌트 네비게이터 팝오버 | K29: 상세 | L29: - | M29: - | N29: 테넌트 네비게이터 팝오버가 표출된 상태 | P29: 1. `전체` 그룹 항목의 북마크 아이콘 확인 | Q29: outline 북마크 아이콘 표출 | R29: PASS | S29: 김미지 | T29: 46296
A30: =ROW()-1 -> 29 | B30: VIOLA_K8S | C30: TC_VIO_044 | F30: VIOE-00_00_00 | G30: P3 | H30: 표시 | I30: 공통 정의 | J30: 테넌트 네비게이터 팝오버 | K30: 상세 | L30: - | M30: - | N30: 팝오버에서 클러스터 1건이 선택된 상태 | P30: 1. 선택 항목 행의 표기 확인 | Q30: 연녹색 배경과 우측 녹색 체크 `✓` 표출 | R30: PASS | S30: 김미지 | T30: 46296
A31: =ROW()-1 -> 30 | B31: VIOLA_K8S | C31: TC_VIO_046 | F31: VIOE-00_00_00 | G31: P3 | H31: 인터랙션 | I31: 공통 정의 | J31: 테넌트 네비게이터 팝오버 | K31: 상세 | L31: - | M31: - | N31: 테넌트 네비게이터 팝오버가 표출된 상태 | P31: 1. 그룹 헤더 우측 정렬 토글 `↑↓` 클릭 | Q31: 항목 정렬 상태 확인 ㄴ "멀티 클러스터 대시보드"는 최상단 고정 | R31: PASS | S31: 김미지 | T31: 46296
A32: =ROW()-1 -> 31 | B32: VIOLA_K8S | C32: TC_VIO_047 | F32: VIOE-00_00_00 | G32: P4 | H32: 부수 | I32: 공통 정의 | J32: 테넌트 네비게이터 팝오버 | K32: 상세 | L32: - | M32: - | N32: 팝오버 그룹이 펼쳐진 상태 | P32: 1. 그룹 헤더 우측 접기 chevron `˅` 클릭 | Q32: 그룹 접힘 상태 확인 | R32: PASS | S32: 김미지 | T32: 46296
A33: =ROW()-1 -> 32 | B33: VIOLA_K8S | C33: TC_VIO_048 | F33: VIOE-00_00_00 | G33: P3 | H33: 표시 | I33: 공통 정의 | J33: 테넌트 네비게이터 팝오버 | K33: 상세 | L33: - | M33: - | N33: 테넌트 네비게이터 팝오버가 표출된 상태 | P33: 1. 팝오버 우하단 최우측 버튼 확인 | Q33: 녹색 채움 `확인` 버튼 표출 | R33: PASS | S33: 김미지 | T33: 46296
... A37: =ROW()-1 -> 36 | B37: VIOLA_K8S | C37: TC_VIO_052 | F37: VIOE-00_00_00 | G37: P2 | H37: 비정상 | I37: 공통 정의 | J37: 테넌트 네비게이터 팝오버 | K37: 상세 | L37: - | M37: - | N37: 테넌트 네비게이터 팝오버가 표출된 상태 | P37: 1. 검색 필드에 일치 항목이 없는 문자열 입력 | Q37: 검색 목록 없음 | R37: PASS | S37: 김미지 | T37: 46296
A38: =ROW()-1 -> 37 | B38: VIOLA_K8S | C38: TC_VIO_056 | F38: VIOE-00_00_09 | G38: P1 | H38: 인터랙션 | I38: 공통 정의 | J38: 모니터링 현황 팝업 | K38: 상세 | L38: - | M38: - | N38: `모니터링 현황` 버튼이 표출된 화면 진입 상태 | P38: 1. 화면 우상단 `모니터링 현황` 버튼 클릭 | Q38: `모니터링 현황` 팝업 표출
A39: =ROW()-1 -> 38 | B39: VIOLA_K8S | C39: TC_VIO_057 | F39: VIOE-00_00_09 | G39: P3 | H39: 표시 | I39: 공통 정의 | J39: 모니터링 현황 팝업 | K39: 상세 | L39: - | M39: - | N39: `모니터링 현황` 팝업이 호출된 상태 | P39: 1. 팝업과 배경 화면의 레이어 순서 확인 | Q39: 팝업이 화면 최상단 레이어로 표출
A40: =ROW()-1 -> 39 | B40: VIOLA_K8S | C40: TC_VIO_058 | F40: VIOE-00_00_09 | G40: P3 | H40: 표시 | I40: 공통 정의 | J40: 모니터링 현황 팝업 | K40: 상세 | L40: - | M40: - | N40: 모니터링 현황 정보 내 장애가 없는 화면 진입 상태 | P40: 1. 화면 우상단 `모니터링 현황` 버튼 표기 확인 | Q40: 녹색 외곽선과 연녹색 배경의 버튼에 라인 차트 아이콘·라벨 `모니터링 현황` 표출
A41: =ROW()-1 -> 40 | B41: VIOLA_K8S | C41: TC_VIO_059 | F41: VIOE-00_00_09 | G41: P3 | H41: 엣지 | I41: 공통 정의 | J41: 모니터링 현황 팝업 | K41: 상세 | L41: - | M41: - | N41: 모니터링 현황 정보 내 장애가 발생한 상태 | P41: 1. 화면 우상단 `모니터링 현황` 버튼 status 확인 | Q41: 버튼 status가 warning status로 변경되어 시각적 알림 효과 표출
A42: =ROW()-1 -> 41 | B42: VIOLA_K8S | C42: TC_VIO_060 | F42: VIOE-00_00_09 | G42: P3 | H42: 표시 | I42: 공통 정의 | J42: 모니터링 현황 팝업 | K42: 상세 | L42: - | M42: - | N42: 모니터링 현황 정보 내 장애로 버튼이 warning status인 상태 | P42: 1. warning status 버튼의 표기 확인 | Q42: 진한 빨강 채움과 빨간 glow 배경에 흰색 아이콘·라벨 표출 ㄴ glow 효과의 애니메이션 여부 기획 미정의 — 해당 부분은 실측 상태를 `실제 결과`에 기재
A43: =ROW()-1 -> 42 | B43: VIOLA_K8S | C43: TC_VIO_061 | F43: VIOE-00_00_09 | G43: P3 | H43: 엣지 | I43: 공통 정의 | J43: 모니터링 현황 팝업 | K43: 상세 | L43: - | M43: - | N43: warning 이벤트만 존재하고 네트워크·로그 통계는 정상인 상태 | P43: 1. 화면 우상단 `모니터링 현황` 버튼 status 확인 | Q43: 이벤트 탭 조건은 버튼 status에 미반영 — 기본 상태 유지
A44: =ROW()-1 -> 43 | B44: VIOLA_K8S | C44: TC_VIO_062 | F44: VIOE-00_00_09 | G44: P3 | H44: 엣지 | I44: 공통 정의 | J44: 모니터링 현황 팝업 | K44: 상세 | L44: - | M44: - | N44: warning 이벤트만 존재하고 네트워크·로그 통계는 정상인 상태 | P44: 1. 화면 우상단 `모니터링 현황` 버튼 status 확인 | Q44: 버튼 status 기본 상태 유지
A45: =ROW()-1 -> 44 | B45: VIOLA_K8S | C45: TC_VIO_063 | F45: VIOE-00_00_09 | G45: P3 | H45: 엣지 | I45: 공통 정의 | J45: 모니터링 현황 팝업 | K45: 상세 | L45: - | M45: - | N45: 네트워크 장애가 존재하는 상태 | P45: 1. 화면 우상단 `모니터링 현황` 버튼 status 확인 | Q45: 버튼 status가 warning status로 변경
A46: =ROW()-1 -> 45 | B46: VIOLA_K8S | C46: TC_VIO_064 | F46: VIOE-00_00_09 | G46: P3 | H46: 엣지 | I46: 공통 정의 | J46: 모니터링 현황 팝업 | K46: 상세 | L46: - | M46: - | N46: 모든 네트워크가 정상이고 미확인 `리소스 상태 이상 감지` 건이 없는 상태 | P46: 1. 화면 우상단 `모니터링 현황` 버튼 status 확인 | Q46: 버튼 status 기본 상태로 표출
A47: =ROW()-1 -> 46 | B47: VIOLA_K8S | C47: TC_VIO_065 | F47: VIOE-00_00_09 | G47: P3 | H47: 엣지 | I47: 공통 정의 | J47: 모니터링 현황 팝업 | K47: 상세 | L47: - | M47: - | N47: 확인하지 않은 `리소스 상태 이상 감지` 건이 존재하는 상태 | P47: 1. 화면 우상단 `모니터링 현황` 버튼 status 확인 | Q47: 버튼 status가 warning status로 변경
A48: =ROW()-1 -> 47 | B48: VIOLA_K8S | C48: TC_VIO_066 | F48: VIOE-00_00_09 | G48: P3 | H48: 엣지 | I48: 공통 정의 | J48: 모니터링 현황 팝업 | K48: 상세 | L48: - | M48: - | N48: 네트워크는 정상이고 미확인 `리소스 상태 이상 감지` 건으로 버튼이 warning status인 상태 | P48: 1. 팝업 탭 `로그 통계` 진입 | Q48: 버튼 status가 기본 상태로 전환
A49: =ROW()-1 -> 48 | B49: VIOLA_K8S | C49: TC_VIO_067 | F49: VIOE-00_00_09 | G49: P3 | H49: 엣지 | I49: 공통 정의 | J49: 모니터링 현황 팝업 | K49: 상세 | L49: - | M49: - | N49: 네트워크 장애와 미확인 `리소스 상태 이상 감지` 건이 동시에 존재하는 상태 | P49: 1. 탭 `로그 통계` 진입 후 `모니터링 현황` 버튼 status 확인 | Q49: 두 조건 동시 성립 시의 버튼 status 확인 ㄴ 기획 미정의 항목 — PASS/FAIL 판정 대신 실측 상태를 `실제 결과`에 기재
...

Sheet 권한_체크리스트(K8s)
B4: VIOLA | O4: 범례 | P4: O | Q4: 기능 제공
P5: ▵ | Q5: 일부 기능 제한
B6: ROLE | F6: 관리자 | I6: 실제 결과 | J6: 수행자 | K6: 수행일자 | L6: Jira | M6: 비고 | P6: 미제공 | Q6: 메뉴 제공X
B7: 자원 | F7: VIOLA(솔루션) | G7: 클러스터 | H7: 네임스페이스
B8: 모니터링 현황 팝업 | E8: 이벤트 탭 | F8: O | G8: O | H8: O
E9: 네트워크 탭 | F9: O | G9: O | H9: ▵ (노드별 네트워크 미제공)
E10: 로그 통계 탭 | F10: O | G10: O | H10: ▵ (운영/보안/노드 로그 미제공)
E11: 알람 이력 탭 | F11: O | G11: O | H11: O
B12: 대시보드 | E12: 멀티 클러스터 대시보드 조회 | F12: ▵ (테넌트 네비게이터 > '멀티 클러스터' 선택 시만) | G12: ▵ (테넌트 네비게이터 > '멀티 클러스터' 선택 시만) | H12: 미제공
E13: 단일 클러스터 대시보드 조회 | F13: O | G13: O | H13: ▵ (네임스페이스 전체 현황 미제공)
B14: 클러스터 관리 | C14: 클러스터설정 | E14: 클러스터 조회 | F14: O | G14: O | H14: ▵ ([진행 현황]탭 미제공)
E15: 클러스터 수정 - 작업 : 노드 스케일링, GPU설정, 업그레이드, 노드 삭제 - 수정 (연결 정보 수정) | F15: O | G15: O | H15: X
E16: 클러스터 연결/생성/삭제/해제 | F16: O | G16: X | H16: X
C17: 노드 관리 | E17: 노드 조회 | F17: O | G17: O | H17: 미제공
E18: 노드 수정 : YAML 수정, 레이블 설정, 무중단 노드스케일링, 사양 변경 | F18: O | G18: O | H18: 미제공
C19: 네임스페이스 관리 | E19: 네임스페이스 조회 | F19: O | G19: O | H19: ▵ ('클러스터 롤 바인딩' 정보 미제공)
E20: 네임스페이스 생성/삭제 | F20: O | G20: O | H20: X
E21: 네임스페이스 수정 : YAML 수정, istio injection 설정 | F21: O | G21: O | H21: O
C22: 백업 통합 관리 | D22: 백업/백업 스케줄 | E22: 조회 | F22: O | G22: 미제공 | H22: 미제공
E23: 생성/삭제 | F23: O | G23: 미제공 | H23: 미제공
D24: 복원 | E24: 복원 조회 | F24: O | G24: 미제공 | H24: 미제공
E25: 복원 생성 | F25: O | G25: 미제공 | H25: 미제공
D26: 삭제 이력 | E26: 조회 | F26: O | G26: 미제공 | H26: 미제공
C27: 리소스 쿼터 설정 | E27: 리소스 쿼터 조회 | F27: O | G27: O | H27: O
E28: 리소스 쿼터 생성/수정/삭제 | F28: O | G28: O | H28: X
C29: 임계치 설정 | E29: 임계치 설정 조회 | F29: O | G29: O | H29: △ (GPU 임계치 불가)
E30: 임계치 설정 생성/수정/삭제 | F30: O | G30: O | H30: △ (GPU 임계치 불가)
C31: 이미지 저장소 | D31: 이미지 저장소 | E31: 이미지 저장소 조회 | F31: O | G31: O | H31: O
E32: 이미지 저장소 등록 | F32: O | G32: O | H32: X
E33: 이미지 저장소 등록 해제 | F33: O | G33: ▵ (본인 등록만) | H33: X
D34: 프로젝트 | E34: 프로젝트 조회 | F34: O | G34: O | H34: O
E35: 프로젝트 생성/수정/삭제 | F35: O | G35: O (기본 이미지저장소 포함) | H35: X
D36: 이미지 | E36: 이미지 조회 | F36: O | G36: O | H36: O
D37: 아티팩트 | E37: 아티팩트 조회 | F37: O | G37: O | H37: O
E38: 이미지 태그 설정/삭제 | F38: O | G38: O | H38: O
E39: 이미지 취약점 검사 | F39: O | G39: O | H39: O
B40: 보안 및 권한 관리 | C40: 서비스 어카운트 | E40: 서비스 어카운트 조회 | F40: O | G40: O | H40: O
E41: 서비스 어카운트 생성/수정/삭제 - kubeconfig 발급 포함 | F41: O | G41: O | H41: O
C42: 롤 | E42: 롤 조회 | F42: O | G42: O | H42: O
E43: 롤 생성/수정/삭제 | F43: O | G43: O | H43: O
...

Sheet 권한_체크리스트(CICD)
B2: VIOLA CI/CD
B4: ROLE | E4: 개발자 | G4: 리드 개발자 | H4: 관리자 | I4: 엔지니어 | J4: 실제 결과 | K4: 수행자 | L4: 수행일자 | M4: Jira | N4: 비고
B5: 자원 | E5: 네임스페이스 | F5: 클러스터 | G5: 클러스터 | H5: VIOLA CI/CD(솔루션)
B6: 대시보드 | D6: 대시보드 | E6: O | F6: O | G6: O | H6: O | I6: 미제공
B7: 파이프라인 설정 | C7: 빌드 관리 | D7: 빌드 조회 | E7: O | F7: O | G7: O * 다른 사용자의 빌드 자원 조회/실행 가능 | H7: O * 다른 사용자의 빌드 자원 조회/실행/수정/삭제 가능 | I7: 미제공
D8: 빌드 실행 | E8: O | F8: O | G8: O | H8: O | I8: 미제공
D9: 빌드 생성/수정/삭제 | E9: O | F9: O | G9: O | H9: O | I9: 미제공
C10: 테스트 관리 | D10: 테스트 조회 | E10: O | F10: O | G10: O * 다른 사용자의 테스트 자원 조회/실행 가능 | H10: O * 다른 사용자의 테스트 자원 조회/실행/수정/삭제 가능 | I10: 미제공
D11: 테스트 실행 | E11: O | F11: O | G11: O | H11: O | I11: 미제공
D12: 테스트 생성/수정/삭제 | E12: O | F12: O | G12: O | H12: O | I12: 미제공
C13: 배포 관리 | D13: 배포 조회 | E13: O | F13: O | G13: O * 다른 사용자의 배포 자원 조회/실행 가능 | H13: O * 다른 사용자의 배포 자원 조회/실행/수정/삭제 가능 | I13: 미제공
D14: 배포 실행/재실행/재배포 | E14: O | F14: O | G14: O | H14: O | I14: 미제공
D15: 배포 생성/수정/삭제 | E15: O | F15: O | G15: O | H15: O | I15: 미제공
C16: 파이프라인 관리 | D16: 파이프라인 조회 | E16: O | F16: O | G16: O * 다른 사용자의 파이프라인 조회/실행 가능 | H16: O * 다른 사용자의 파이프라인 조회/실행/중단/수정/삭제 가능 | I16: 미제공
D17: 파이프라인 실행/중단 | E17: O | F17: O | G17: O | H17: O | I17: 미제공
D18: 파이프라인 생성/수정/삭제 | E18: O | F18: O | G18: O | H18: O | I18: 미제공
C19: 템플릿 관리 | D19: 템플릿 조회 | E19: O | F19: O | G19: O * 공유 옵션이 off 인 경우 다른 사용자가 생성한 템플릿 조회 불가능 | H19: O * 공유 옵션이 off 여도 다른 사용자가 생성한 템플릿 조회 가능 | I19: 미제공
D20: 템플릿 생성/수정/삭제 | E20: O | F20: O | G20: O * 다른 사용자가 생성한 템플릿 수정/삭제 가능 | H20: O * 다른 사용자가 생성한 템플릿 수정/삭제 가능 | I20: 미제공
B21: 저장소 관리 | C21: 소스 코드 저장소 | D21: 소스 코드 저장소 조회 | E21: O | F21: O | G21: O | H21: O * 다른 사용자가 등록한 저장소 조회/수정/등록 해제 가능 | I21: 미제공
D22: 소스 코드 저장소 수정 | E22: O | F22: O | G22: O | H22: O | I22: 미제공
D23: 소스 코드 저장소 등록/해제 | E23: O | F23: O | G23: O | H23: O | I23: 미제공
C24: 이미지 저장소 | D24: 이미지 저장소 조회 | E24: O | F24: O | G24: O | H24: O | I24: 미제공
D25: 이미지 저장소 등록 | E25: X | F25: O | G25: O | H25: O | I25: 미제공
D26: 이미지 저장소 등록 해제 | E26: X | F26: ▵ * 본인이 등록한 저장소만 등록 해제 가능 | G26: O | H26: O | I26: 미제공
D27: 프로젝트 조회 | E27: O | F27: O | G27: O | H27: O | I27: 미제공
D28: 프로젝트 생성/수정/삭제 | E28: X | F28: O (기본 이미지 저장소 포함) | G28: O (기본 이미지 저장소 포함) | H28: O (기본 이미지 저장소 포함) | I28: 미제공
D29: 이미지 조회 | E29: O | F29: O | G29: O | H29: O | I29: 미제공
D30: 아티팩트 조회 | E30: O | F30: O | G30: O | H30: O | I30: 미제공
D31: 이미지 태그 설정/삭제 | E31: O | F31: O | G31: O | H31: O | I31: 미제공
D32: 이미지 취약점 검사 | E32: O | F32: O | G32: O | H32: O | I32: 미제공
B33: 애플리케이션 | C33: 토폴로지 | D33: 토폴로지 조회 | E33: O | F33: O | G33: O * 다른 사용자의 토폴로지 조회/수정/삭제 가능 | H33: O * 다른 사용자의 토폴로지 조회/수정/삭제 가능 | I33: 미제공
D34: 토폴로지 생성/수정/삭제 | E34: O | F34: O | G34: O | H34: O | I34: 미제공
C35: 성능 모니터링 | D35: 성능 모니터링 조회 | E35: O | F35: O | G35: O * 다른 사용자의 성능 모니터링 조회 가능 | H35: O * 다른 사용자의 성능 모니터링 조회 가능 | I35: 미제공
B36: 서비스 카탈로그 | C36: 카탈로그 허브 (탭) | D36: 서비스 카탈로그 조회 | E36: O | F36: O | G36: O | H36: O | I36: 미제공
D37: HelmChart/YAML 생성/수정/삭제 | E37: X | F37: ▵ * 본인이 생성한 경우에만 가능 | G37: O | H37: O | I37: 미제공
D38: HelmChart/YAML 실행 | E38: O | F38: O | G38: O | H38: O | I38: 미제공
D39: VIOLA 컴포넌트 설치 | E39: X | F39: O | G39: O | H39: O | I39: 미제공
C40: 설치 목록 (탭) | D40: 설치 목록 조회 | E40: O | F40: O | G40: O | H40: O | I40: 미제공
D41: VIOLA 컴포넌트 롤백/수정/삭제 | E41: X | F41: O | G41: O | H41: O | I41: 미제공
D42: HelmChart 롤백/수정/삭제 (VIOLA 컴포넌트 제외) | E42: O | F42: O | G42: O | H42: O | I42: 미제공
...

Sheet 수정
A1: No | B1: 솔루션 | C1: 기능테스트 ID | D1: 요구사항 ID | E1: 기능 ID | F1: 화면 ID | G1: 우선순위 | H1: 구분 | I1: 1 Depth | J1: 2 Depth | K1: 3 Depth | L1: 4 Depth | M1: 5 Depth | N1: 사전조건 | O1: 테스트 데이터 | P1: 절차 | Q1: 예상 결과 | R1: 실제 결과 | S1: 수행자 | T1: 수행일자 | U1: Jira | V1: 비고
A2: 1 | B2: VIOLA | C2: TC_VIO_001 | F2: VIOE-00_00_00 | G2: P3 | H2: 표시 | I2: 공통 정의 | J2: 레이아웃 정의 | K2: 상세 | L2: - | M2: - | N2: VIOLA 로그인 후 레이아웃이 적용된 화면 진입 | P2: 1. 화면 상단 GNB 영역 확인 | Q2: GNB 영역 구성 확인 ㄴ 기획 미정의 항목 — PASS/FAIL 판정 대신 실측 상태를 `실제 결과`에 기재 | V2: [DESC 머리] GNB 영역은 Boot Factory 참고 | W2: [정책 예외] 문서 기본=변경 / 이 화면=신규 [확인 불가] U-2 GNB 상세 정의가 타 제품(Boot Factory) 기획서로 위임 — 해당 기획서 확인 필요
A3: 2 | B3: VIOLA | C3: TC_VIO_002 | F3: VIOE-00_00_00 | G3: P3 | H3: 표시 | I3: 공통 정의 | J3: 레이아웃 정의 | K3: 상세 | L3: - | M3: - | N3: 레이아웃 적용 화면 진입 직후 상태 | P3: 1. LNB 영역의 메뉴 목록 확인 | Q3: 메뉴 `대시보드`·`기본 설정`·`워크플로우`·`서비스 카탈로그`·`모니터링` 5종 표출 | V3: [DESC 1항] [UI] p15 LNB 영역 메뉴 목록 | W3: [정책 예외] 문서 기본=변경 / 이 화면=신규
A4: 3 | B4: VIOLA | C4: TC_VIO_003 | F4: VIOE-00_00_00 | G4: P3 | H4: 표시 | I4: 공통 정의 | J4: 레이아웃 정의 | K4: 상세 | L4: - | M4: - | N4: 레이아웃 적용 화면 진입 직후 상태 | P4: 1. LNB 메뉴 목록을 Menu Structure 정의와 대조 | Q4: LNB 메뉴 구성 확인 ㄴ 기획 미정의 항목 — PASS/FAIL 판정 대신 실측 상태를 `실제 결과`에 기재 | V4: [DESC 1항-1] [공통 DESC C19] VIOLA LNB 메뉴 제공(Menu Structure 참고) | W4: [정책 예외] 문서 기본=변경 / 이 화면=신규 [확인 불가] U-12 메뉴 트리 원문이 Menu Structure(p9) 위임 — 이 화면 근거로 확정 불가, 기획 확인 필요
A5: 4 | B5: VIOLA | C5: TC_VIO_004 | F5: VIOE-00_00_00 | G5: P3 | H5: 표시 | I5: 공통 정의 | J5: 레이아웃 정의 | K5: 상세 | L5: - | M5: - | N5: 레이아웃 적용 화면 최초 진입 상태 | P5: 1. LNB 상위 메뉴의 펼침 상태 확인 | Q5: 전체 메뉴 닫힘 상태로 표출 | V5: [DESC 1항-2] `Default : 전체 닫힘` | W5: [정책 예외] 문서 기본=변경 / 이 화면=신규
A6: 5 | B6: VIOLA | C6: TC_VIO_005 | F6: VIOE-00_00_00 | G6: P3 | H6: 표시 | I6: 공통 정의 | J6: 레이아웃 정의 | K6: 상세 | L6: - | M6: - | N6: 레이아웃 적용 화면 최초 진입 상태 | P6: 1. LNB 메뉴의 선택 상태 확인 | Q6: `대시보드` 메뉴 선택 상태로 표출 | V6: [DESC 1항-2-a] 대시보드 메뉴 선택된 상태 | W6: [정책 예외] 문서 기본=변경 / 이 화면=신규
A7: 6 | B7: VIOLA | C7: TC_VIO_006 | F7: VIOE-00_00_00 | G7: P3 | H7: 표시 | I7: 공통 정의 | J7: 레이아웃 정의 | K7: 상세 | L7: - | M7: - | N7: 레이아웃 적용 화면 최초 진입 상태 | P7: 1. 하위 메뉴 보유 메뉴의 chevron 표기 확인 | Q7: `기본 설정`·`워크플로우`·`서비스 카탈로그`·`모니터링` 우측에 chevron `˅` 표출 | V7: [UI] p15 LNB 메뉴 chevron 표기 4종 | W7: [정책 예외] 문서 기본=변경 / 이 화면=신규
A8: 7 | B8: VIOLA | C8: TC_VIO_007 | F8: VIOE-00_00_00 | G8: P4 | H8: 부수 | I8: 공통 정의 | J8: 레이아웃 정의 | K8: 상세 | L8: - | M8: - | N8: LNB 전체 메뉴 닫힘 상태 | P8: 1. 하위 메뉴가 없는 `대시보드` 메뉴 클릭 | Q8: chevron 미표기로 하위 메뉴 펼침 미발생 | V8: [UI] p15 대시보드 chevron 미표기 [DESC 1항-4] 하위 메뉴 없는 메뉴 | W8: [정책 예외] 문서 기본=변경 / 이 화면=신규
A9: 8 | B9: VIOLA | C9: TC_VIO_008 | F9: VIOE-00_00_00 | G9: P3 | H9: 인터랙션 | I9: 공통 정의 | J9: 레이아웃 정의 | K9: 상세 | L9: - | M9: - | N9: LNB 전체 메뉴 닫힘 상태 | P9: 1. 상위 메뉴 `기본 설정` 클릭 | Q9: `기본 설정` 하위 메뉴 펼침 | V9: [DESC 1항-3] 상위 메뉴 클릭 시, 하위 메뉴 펼침 | W9: [정책 예외] 문서 기본=변경 / 이 화면=신규
A10: 9 | B10: VIOLA | C10: TC_VIO_009 | F10: VIOE-00_00_00 | G10: P3 | H10: 엣지 | I10: 공통 정의 | J10: 레이아웃 정의 | K10: 상세 | L10: - | M10: - | N10: 상위 메뉴 `기본 설정` 하위 메뉴가 펼쳐진 상태 | P10: 1. 상위 메뉴 `기본 설정` 재클릭 | Q10: 재클릭 후 하위 메뉴 상태 확인 ㄴ 기획 미정의 항목 — PASS/FAIL 판정 대신 실측 상태를 `실제 결과`에 기재 | V10: [확인 불가 기반] [DESC 1항-3] 펼침만 규정, 접힘 미규정 | W10: [정책 예외] 문서 기본=변경 / 이 화면=신규 [확인 불가] U-11 상위 메뉴 재클릭 시 접힘 여부 미정의 — 기획 확인 필요
A11: 10 | B11: VIOLA | C11: TC_VIO_010 | F11: VIOE-00_00_00 | G11: P3 | H11: 엣지 | I11: 공통 정의 | J11: 레이아웃 정의 | K11: 상세 | L11: - | M11: - | N11: 상위 메뉴 `기본 설정` 하위 메뉴가 펼쳐진 상태 | P11: 1. 다른 상위 메뉴 `워크플로우` 클릭 | Q11: 두 상위 메뉴의 펼침 상태 확인 ㄴ 기획 미정의 항목 — PASS/FAIL 판정 대신 실측 상태를 `실제 결과`에 기재 | V11: [확인 불가 기반] [DESC 1항-3] 동시 펼침 허용 개수 미규정 | W11: [정책 예외] 문서 기본=변경 / 이 화면=신규 [확인 불가] U-11 동시 펼침 허용 개수 미정의 — 기획 확인 필요
A12: 11 | B12: VIOLA | C12: TC_VIO_011 | F12: VIOE-00_00_00 | G12: P3 | H12: 엣지 | I12: 공통 정의 | J12: 레이아웃 정의 | K12: 상세 | L12: - | M12: - | N12: 복수 상위 메뉴의 하위 메뉴가 펼쳐진 상태 | P12: 1. 하위 메뉴가 없는 메뉴 진입 | Q12: 진입한 메뉴 외 전체 메뉴 닫힘 | V12: [DESC 1항-4-a] 진입한 메뉴 외 전체 메뉴 닫힘 | W12: [정책 예외] 문서 기본=변경 / 이 화면=신규 [확인 불가] 대상 리프 메뉴는 Menu Structure(p9) 확인 필요
A13: 12 | B13: VIOLA | C13: TC_VIO_012 | F13: VIOE-00_00_00 | G13: P3 | H13: 엣지 | I13: 공통 정의 | J13: 레이아웃 정의 | K13: 상세 | L13: - | M13: - | N13: 상위 메뉴 하위의 하위 메뉴 없는 메뉴에 진입한 상태 | P13: 1. 진입한 메뉴의 상위 메뉴 펼침 상태 확인 | Q13: 진입한 메뉴의 상위 메뉴만 펼침 상태 유지 | V13: [DESC 1항-4-a-1] 진입한 메뉴의 상위 메뉴만 펼침 상태 유지 | W13: [정책 예외] 문서 기본=변경 / 이 화면=신규 [확인 불가] 대상 리프 메뉴는 Menu Structure(p9) 확인 필요
... A1001: 1000 | B1001: VIOLA | C1001: TC_VIO_1000 | F1001: VIOE-03_01_04_14 | G1001: P2 | H1001: 비정상 | I1001: 워크플로우 | J1001: HPA 스케줄 생성 | K1001: 생성 | L1001: - | M1001: - | N1001: 스케줄 첫 행의 `예약일시` 가 설정된 상태에서 이전 스케줄 행이 없고 `종료일시` Picker 를 연 상태 | P1001: 1. Picker 에서 `예약일시` 이전 일시로 설정 시도 | Q1001: 오류 메시지 `예약 시간 이후로 설정해 주세요.` 표출 | V1001: [DESC 2항-2-d3] 예약일시 이전으로 선택 시 오류 메시지 제공 | W1001: [정책 예외] 문서 기본=변경 / 이 화면=신규 [오타 의심] T-3 규정 본문은 `예약일자`, 오류 문구는 `예약 시간` 으로 어휘가 갈림 — 표기 통일 확인 필요

Sheet 기획 문의
B2: 질문 영역 | G2: 답변 내용
B3: 질문 팀/파트 | C3: 화면ID | D3: 구분 (기능명) | E3: 문의 내용 | F3: 문의자 | G3: 답변 내용 | H3: 답변자 | I3: 비고
B4: 품질팀 | C4: VIO-02_01_01-04 | D4: 클러스터 생성(1/3) | E4: 쿠버네티스 엔진 버전이 "솔루션 버전별 상이" 기재되어 있음 -> 4.0 에 클러스터 지원버전 변경점이 있는지 문의 | F4: 김미지
C5: VIO-02_01_01-14 | D5: 클러스터 생성(2/3) - 기존 노드 사용 | E5: 기존 노드 사용 옵션은 컨트롤 플레인, 워커 노드의 IP 구성 시 기존에 생성했던 노드의 IP 를 작성하는건지? | F5: 김미지
B6: 품질팀 | C6: VIO-02_01_01-11 | D6: 엔진 업그레이드 팝업(1/2) | E6: 현재 버전이 미지원 버전으로 설정되었을 경우"엔진 업그레이드 팝업 > 생성된 클러스터만 제공하는 기능으로 1.31,1.32,1.33 으로 생성 가능함 현재 버전이 미지원 버전을 가진 클러스터를 어떻게 만들 수 있는지? | F6: 김미지
B7: 품질팀 | C7: VIO-04_06_02 | D7: 모니터링 > 외부 알람 설정 | E7: 클러스터 이상 감지버튼은 구분이 표출되지 않는지 - 구분에 메트릭, 이벤트, 로그 구분 TAG 로만 표출이라고 기획서에 정의되어 있음 | F7: 김미지
